Traceback (most recent call last):
  File "/home/ds6237/.conda/envs/grpo/lib/python3.10/site-packages/urllib3/connection.py", line 198, in _new_conn
    sock = connection.create_connection(
  File "/home/ds6237/.conda/envs/grpo/lib/python3.10/site-packages/urllib3/util/connection.py", line 60, in create_connection
    for res in socket.getaddrinfo(host, port, family, socket.SOCK_STREAM):
  File "/home/ds6237/.conda/envs/grpo/lib/python3.10/socket.py", line 967, in getaddrinfo
    for res in _socket.getaddrinfo(host, port, family, type, proto, flags):
socket.gaierror: [Errno -2] Name or service not known

The above exception was the direct cause of the following exception:

Traceback (most recent call last):
  File "/home/ds6237/.conda/envs/grpo/lib/python3.10/site-packages/urllib3/connectionpool.py", line 787, in urlopen
    response = self._make_request(
  File "/home/ds6237/.conda/envs/grpo/lib/python3.10/site-packages/urllib3/connectionpool.py", line 488, in _make_request
    raise new_e
  File "/home/ds6237/.conda/envs/grpo/lib/python3.10/site-packages/urllib3/connectionpool.py", line 464, in _make_request
    self._validate_conn(conn)
  File "/home/ds6237/.conda/envs/grpo/lib/python3.10/site-packages/urllib3/connectionpool.py", line 1093, in _validate_conn
    conn.connect()
  File "/home/ds6237/.conda/envs/grpo/lib/python3.10/site-packages/urllib3/connection.py", line 704, in connect
    self.sock = sock = self._new_conn()
  File "/home/ds6237/.conda/envs/grpo/lib/python3.10/site-packages/urllib3/connection.py", line 205, in _new_conn
    raise NameResolutionError(self.host, self, e) from e
urllib3.exceptions.NameResolutionError: <urllib3.connection.HTTPSConnection object at 0x147d326d2170>: Failed to resolve 'huggingface.co' ([Errno -2] Name or service not known)

The above exception was the direct cause of the following exception:

Traceback (most recent call last):
  File "/home/ds6237/.conda/envs/grpo/lib/python3.10/site-packages/requests/adapters.py", line 667, in send
    resp = conn.urlopen(
  File "/home/ds6237/.conda/envs/grpo/lib/python3.10/site-packages/urllib3/connectionpool.py", line 841, in urlopen
    retries = retries.increment(
  File "/home/ds6237/.conda/envs/grpo/lib/python3.10/site-packages/urllib3/util/retry.py", line 519, in increment
    raise MaxRetryError(_pool, url, reason) from reason  # type: ignore[arg-type]
urllib3.exceptions.MaxRetryError: HTTPSConnectionPool(host='huggingface.co', port=443): Max retries exceeded with url: /api/models/unsloth/meta-llama-3.1-8b-instruct-unsloth-bnb-4bit/tree/main?recursive=True&expand=False (Caused by NameResolutionError("<urllib3.connection.HTTPSConnection object at 0x147d326d2170>: Failed to resolve 'huggingface.co' ([Errno -2] Name or service not known)"))

During handling of the above exception, another exception occurred:

Traceback (most recent call last):
  File "/home/ds6237/.conda/envs/grpo/lib/python3.10/site-packages/unsloth_zoo/vllm_utils.py", line 1028, in load_vllm
    llm = LLM(**engine_args)
  File "/home/ds6237/.conda/envs/grpo/lib/python3.10/site-packages/vllm/utils.py", line 1037, in inner
    return fn(*args, **kwargs)
  File "/home/ds6237/.conda/envs/grpo/lib/python3.10/site-packages/vllm/entrypoints/llm.py", line 243, in __init__
    self.llm_engine = LLMEngine.from_engine_args(
  File "/home/ds6237/.conda/envs/grpo/lib/python3.10/site-packages/vllm/engine/llm_engine.py", line 513, in from_engine_args
    vllm_config = engine_args.create_engine_config(usage_context)
  File "/home/ds6237/.conda/envs/grpo/lib/python3.10/site-packages/vllm/engine/arg_utils.py", line 1296, in create_engine_config
    model_config = self.create_model_config()
  File "/home/ds6237/.conda/envs/grpo/lib/python3.10/site-packages/vllm/engine/arg_utils.py", line 1141, in create_model_config
    return ModelConfig(
  File "/home/ds6237/.conda/envs/grpo/lib/python3.10/site-packages/vllm/config.py", line 413, in __init__
    supported_tasks, task = self._resolve_task(task)
  File "/home/ds6237/.conda/envs/grpo/lib/python3.10/site-packages/vllm/config.py", line 580, in _resolve_task
    preferred_task = self._get_preferred_task(
  File "/home/ds6237/.conda/envs/grpo/lib/python3.10/site-packages/vllm/config.py", line 522, in _get_preferred_task
    if get_pooling_config(model_id, self.revision):
  File "/home/ds6237/.conda/envs/grpo/lib/python3.10/site-packages/vllm/transformers_utils/config.py", line 428, in get_pooling_config
    if file_or_path_exists(model=model,
  File "/home/ds6237/.conda/envs/grpo/lib/python3.10/site-packages/vllm/transformers_utils/config.py", line 179, in file_or_path_exists
    return file_exists(str(model),
  File "/home/ds6237/.conda/envs/grpo/lib/python3.10/site-packages/vllm/transformers_utils/config.py", line 154, in file_exists
    file_list = list_repo_files(repo_id,
  File "/home/ds6237/.conda/envs/grpo/lib/python3.10/site-packages/vllm/transformers_utils/config.py", line 143, in list_repo_files
    return with_retry(lookup_files, "Error retrieving file list")
  File "/home/ds6237/.conda/envs/grpo/lib/python3.10/site-packages/vllm/transformers_utils/config.py", line 97, in with_retry
    return func()
  File "/home/ds6237/.conda/envs/grpo/lib/python3.10/site-packages/vllm/transformers_utils/config.py", line 133, in lookup_files
    return hf_list_repo_files(repo_id,
  File "/home/ds6237/.conda/envs/grpo/lib/python3.10/site-packages/huggingface_hub/utils/_validators.py", line 114, in _inner_fn
    return fn(*args, **kwargs)
  File "/home/ds6237/.conda/envs/grpo/lib/python3.10/site-packages/huggingface_hub/hf_api.py", line 2994, in list_repo_files
    return [
  File "/home/ds6237/.conda/envs/grpo/lib/python3.10/site-packages/huggingface_hub/hf_api.py", line 2994, in <listcomp>
    return [
  File "/home/ds6237/.conda/envs/grpo/lib/python3.10/site-packages/huggingface_hub/hf_api.py", line 3131, in list_repo_tree
    for path_info in paginate(path=tree_url, headers=headers, params={"recursive": recursive, "expand": expand}):
  File "/home/ds6237/.conda/envs/grpo/lib/python3.10/site-packages/huggingface_hub/utils/_pagination.py", line 36, in paginate
    r = session.get(path, params=params, headers=headers)
  File "/home/ds6237/.conda/envs/grpo/lib/python3.10/site-packages/requests/sessions.py", line 602, in get
    return self.request("GET", url, **kwargs)
  File "/home/ds6237/.conda/envs/grpo/lib/python3.10/site-packages/requests/sessions.py", line 589, in request
    resp = self.send(prep, **send_kwargs)
  File "/home/ds6237/.conda/envs/grpo/lib/python3.10/site-packages/requests/sessions.py", line 703, in send
    r = adapter.send(request, **kwargs)
  File "/home/ds6237/.conda/envs/grpo/lib/python3.10/site-packages/huggingface_hub/utils/_http.py", line 96, in send
    return super().send(request, *args, **kwargs)
  File "/home/ds6237/.conda/envs/grpo/lib/python3.10/site-packages/requests/adapters.py", line 700, in send
    raise ConnectionError(e, request=request)
requests.exceptions.ConnectionError: (MaxRetryError('HTTPSConnectionPool(host=\'huggingface.co\', port=443): Max retries exceeded with url: /api/models/unsloth/meta-llama-3.1-8b-instruct-unsloth-bnb-4bit/tree/main?recursive=True&expand=False (Caused by NameResolutionError("<urllib3.connection.HTTPSConnection object at 0x147d326d2170>: Failed to resolve \'huggingface.co\' ([Errno -2] Name or service not known)"))'), '(Request ID: 604b050e-b759-483d-b952-5e6c5abc1b3c)')

During handling of the above exception, another exception occurred:

Traceback (most recent call last):
  File "/home/ds6237/EntropicReasoners/baseline_offline.py", line 15, in <module>
    model, tokenizer = FastLanguageModel.from_pretrained(
  File "/home/ds6237/.conda/envs/grpo/lib/python3.10/site-packages/unsloth/models/loader.py", line 363, in from_pretrained
    model, tokenizer = dispatch_model.from_pretrained(
  File "/home/ds6237/.conda/envs/grpo/lib/python3.10/site-packages/unsloth/models/llama.py", line 1819, in from_pretrained
    llm = load_vllm(**load_vllm_kwargs)
  File "/home/ds6237/.conda/envs/grpo/lib/python3.10/site-packages/unsloth_zoo/vllm_utils.py", line 1051, in load_vllm
    raise RuntimeError(error)
RuntimeError: (MaxRetryError('HTTPSConnectionPool(host=\'huggingface.co\', port=443): Max retries exceeded with url: /api/models/unsloth/meta-llama-3.1-8b-instruct-unsloth-bnb-4bit/tree/main?recursive=True&expand=False (Caused by NameResolutionError("<urllib3.connection.HTTPSConnection object at 0x147d326d2170>: Failed to resolve \'huggingface.co\' ([Errno -2] Name or service not known)"))'), '(Request ID: 604b050e-b759-483d-b952-5e6c5abc1b3c)')
